Workbook

Sheet Capa
A1: PT_calculos_COPEL_2025 - Planilhas editáveis do dossiê
A3: Trabalho | B3: Dossiê de auditoria acadêmico - P2 - Auditoria (UnB)
A4: Estudante | B4: Daiane da Silva - matrícula 232025417
A5: Companhia | B5: Companhia Paranaense de Energia - COPEL - CNPJ 76.483.817/0001-20 - Código CVM 1431-1
A6: Exercício | B6: 31/12/2025 (comparativo 31/12/2024) - demonstrações consolidadas
A7: Data de consulta das fontes | B7: 24/10/2026
A8: Natureza | B8: Trabalho acadêmico realizado com apoio de IA. NÃO é opinião profissional independente.
A9: Dados sintéticos | B9: Abas MUS_*, Excecoes, Distorcoes (parte simulada) e Conciliacao_Intangivel (base) usam DADOS SINTÉTICOS gerados por código; não são registros reais da COPEL.
A10: Unidade | B10: R$ mil, salvo indicação (R$ = reais nas abas da base sintética).
A11: Cores | B11: Azul = entrada (fonte pública/premissa) | Preto = fórmula | Verde = vínculo entre abas | Amarelo = premissa de julgamento editável
A12: Revisão | B12: Campo de revisão não preenchido: não há revisão de terceiros.

Sheet BP
A1: Balanço patrimonial consolidado (R$ mil) - PT 520 / PT 320
A2: COPEL - exercício 2025 | Preparadora: matrícula 232025417 | Data: 24/10/2026 | Revisão: ____________ (campo não preenchido - sem revisão de terceiros)
A3: Fonte: F01, Anexo I, p. 24 (release 4T25, Form 6-K, SEC, 27/02/2026)
A5: Rubrica | B5: 31/12/2025 | C5: 31/12/2024 | D5: Variação R$ | E5: Variação % | F5: AV % 2025 | G5: Checagem
A6: Ativo circulante
A7: Caixa e equivalentes de caixa | B7: 3130363 | C7: 4161939 | D7: =B7-C7 -> -1031576 | E7: =IF(C7=0,"",D7/C7) -> -0.24785947 | F7: =B7/B$48 -> 0.051814801
A8: Títulos e valores mobiliários | B8: 895 | C8: 623 | D8: =B8-C8 -> 272 | E8: =IF(C8=0,"",D8/C8) -> 0.43659711 | F8: =B8/B$48 -> 1.4814335e-05
A9: Cauções e depósitos vinculados | B9: 9 | C9: 9 | D9: =B9-C9 -> 0 | E9: =IF(C9=0,"",D9/C9) -> 0 | F9: =B9/B$48 -> 1.4897097e-07
A10: Clientes | B10: 4300957 | C10: 3962702 | D10: =B10-C10 -> 338255 | E10: =IF(C10=0,"",D10/C10) -> 0.085359686 | F10: =B10/B$48 -> 0.071190859
A11: Dividendos a receber | B11: 141297 | C11: 82278 | D11: =B11-C11 -> 59019 | E11: =IF(C11=0,"",D11/C11) -> 0.71731204 | F11: =B11/B$48 -> 0.0023387945
A12: Ativos financeiros setoriais | B12: 400463 | C12: 0 | D12: =B12-C12 -> 400463 | E12: =IF(C12=0,"",D12/C12) | F12: =B12/B$48 -> 0.0066285956
A13: Contas a receber vinculadas à concessão | B13: 12867 | C13: 10609 | D13: =B13-C13 -> 2258 | E13: =IF(C13=0,"",D13/C13) -> 0.21283816 | F13: =B13/B$48 -> 0.00021297883
A14: Ativos de contrato | B14: 392594 | C14: 283896 | D14: =B14-C14 -> 108698 | E14: =IF(C14=0,"",D14/C14) -> 0.38287965 | F14: =B14/B$48 -> 0.0064983454
A15: Valor justo nas operações de compra e venda de energia | B15: 263645 | C15: 217350 | D15: =B15-C15 -> 46295 | E15: =IF(C15=0,"",D15/C15) -> 0.21299747 | F15: =B15/B$48 -> 0.004363939
A16: Outros créditos | B16: 1050086 | C16: 949674 | D16: =B16-C16 -> 100412 | E16: =IF(C16=0,"",D16/C16) -> 0.10573313 | F16: =B16/B$48 -> 0.01738137
A17: Estoques | B17: 173398 | C17: 136324 | D17: =B17-C17 -> 37074 | E17: =IF(C17=0,"",D17/C17) -> 0.27195505 | F17: =B17/B$48 -> 0.0028701409
A18: Imposto de renda e contribuição social a recuperar | B18: 502825 | C18: 296128 | D18: =B18-C18 -> 206697 | E18: =IF(C18=0,"",D18/C18) -> 0.69799884 | F18: =B18/B$48 -> 0.0083229252
... A22: Ativos classificados como mantidos para venda | B22: 25177 | C22: 1881826 | D22: =B22-C22 -> -1856649 | E22: =IF(C22=0,"",D22/C22) -> -0.98662097 | F22: =B22/B$48 -> 0.00041673801
A23: Total ativo circulante (soma) | B23: =SUM(B7:B22) -> 10881654 | C23: =SUM(C7:C22) -> 13041808 | D23: =B23-C23 -> -2160154 | E23: =IF(C23=0,"",D23/C23) -> -0.16563302 | F23: =B23/B$48 -> 0.18011673 | G23: =IF(AND(B23=10881654,C23=13041808),"Confere com publicado","DIFERENÇA") -> Confere com publicado
A25: Realizável a longo prazo
A26: Títulos e valores mobiliários | B26: 690886 | C26: 529085 | D26: =B26-C26 -> 161801 | E26: =IF(C26=0,"",D26/C26) -> 0.30581287 | F26: =B26/B$48 -> 0.011435773
A27: Outros investimentos temporários | B27: 30627 | C27: 30603 | D27: =B27-C27 -> 24 | E27: =IF(C27=0,"",D27/C27) -> 0.00078423684 | F27: =B27/B$48 -> 0.0005069482
A28: Clientes | B28: 162189 | C28: 116180 | D28: =B28-C28 -> 46009 | E28: =IF(C28=0,"",D28/C28) -> 0.3960148 | F28: =B28/B$48 -> 0.0026846058
A29: Depósitos judiciais | B29: 373949 | C29: 394364 | D29: =B29-C29 -> -20415 | E29: =IF(C29=0,"",D29/C29) -> -0.051766896 | F29: =B29/B$48 -> 0.0061897272
A30: Ativos financeiros setoriais | B30: 400463 | C30: 0 | D30: =B30-C30 -> 400463 | E30: =IF(C30=0,"",D30/C30) | F30: =B30/B$48 -> 0.0066285956
A31: Contas a receber vinculadas à concessão | B31: 4590579 | C31: 3497351 | D31: =B31-C31 -> 1093228 | E31: =IF(C31=0,"",D31/C31) -> 0.31258744 | F31: =B31/B$48 -> 0.075984778
A32: Ativos de contrato | B32: 9202412 | C32: 6927010 | D32: =B32-C32 -> 2275402 | E32: =IF(C32=0,"",D32/C32) -> 0.32848256 | F32: =B32/B$48 -> 0.15232136
A33: Valor justo nas operações de compra e venda de energia | B33: 597856 | C33: 479938 | D33: =B33-C33 -> 117918 | E33: =IF(C33=0,"",D33/C33) -> 0.24569424 | F33: =B33/B$48 -> 0.0098959097
A34: Outros créditos | B34: 794296 | C34: 681846 | D34: =B34-C34 -> 112450 | E34: =IF(C34=0,"",D34/C34) -> 0.16491994 | F34: =B34/B$48 -> 0.013147449
A35: Imposto de renda e contribuição social a recuperar | B35: 102589 | C35: 164043 | D35: =B35-C35 -> -61454 | E35: =IF(C35=0,"",D35/C35) -> -0.37462129 | F35: =B35/B$48 -> 0.001698087
A36: Imposto de renda e contribuição social diferidos | B36: 991404 | C36: 1174175 | D36: =B36-C36 -> -182771 | E36: =IF(C36=0,"",D36/C36) -> -0.15565908 | F36: =B36/B$48 -> 0.016410046
A37: Outros tributos a recuperar | B37: 1127582 | C37: 1320526 | D37: =B37-C37 -> -192944 | E37: =IF(C37=0,"",D37/C37) -> -0.14611147 | F37: =B37/B$48 -> 0.018664109
A38: Despesas antecipadas | B38: 507 | C38: 0 | D38: =B38-C38 -> 507 | E38: =IF(C38=0,"",D38/C38) | F38: =B38/B$48 -> 8.3920312e-06
A39: Total realizável a longo prazo (soma) | B39: =SUM(B26:B38) -> 19065339 | C39: =SUM(C26:C38) -> 15315121 | D39: =B39-C39 -> 3750218 | E39: =IF(C39=0,"",D39/C39) -> 0.24487028 | F39: =B39/B$48 -> 0.31557578 | G39: =IF(AND(B39=19065339,C39=15315121),"Confere com publicado","DIFERENÇA") -> Confere com publicado
A41: Investimentos, imobilizado e intangível
A42: Investimentos | B42: 2849002 | C42: 3577937 | D42: =B42-C42 -> -728935 | E42: =IF(C42=0,"",D42/C42) -> -0.20373053 | F42: =B42/B$48 -> 0.047157621
A43: Imobilizado | B43: 8145552 | C43: 8516697 | D43: =B43-C43 -> -371145 | E43: =IF(C43=0,"",D43/C43) -> -0.043578514 | F43: =B43/B$48 -> 0.13482786
A44: Intangível | B44: 19206609 | C44: 16623610 | D44: =B44-C44 -> 2582999 | E44: =IF(C44=0,"",D44/C44) -> 0.15538135 | F44: =B44/B$48 -> 0.31791413
A45: Direito de uso de ativos | B45: 266300 | C45: 308983 | D45: =B45-C45 -> -42683 | E45: =IF(C45=0,"",D45/C45) -> -0.13814029 | F45: =B45/B$48 -> 0.0044078854
A46: Total investimentos, imobilizado e intangível (soma) | B46: =SUM(B42:B45) -> 30467463 | C46: =SUM(C42:C45) -> 29027227 | D46: =B46-C46 -> 1440236 | E46: =IF(C46=0,"",D46/C46) -> 0.049616727 | F46: =B46/B$48 -> 0.5043075 | G46: =IF(AND(B46=30467463,C46=29027227),"Confere com publicado","DIFERENÇA") -> Confere com publicado
...

Sheet DRE
A1: Demonstração do resultado consolidada (R$ mil) - PT 520 / PT PA-01
A2: COPEL - exercício 2025 | Preparadora: matrícula 232025417 | Data: 24/10/2026 | Revisão: ____________ (campo não preenchido - sem revisão de terceiros)
A3: Fonte: F01, Anexo I, p. 23. 'Outros custos e despesas' 2024 inclui (936) de material para energia elétrica, apresentado em linha separada no release.
A5: Rubrica | B5: 2025 | C5: 2024 | D5: Variação R$ | E5: Variação % | F5: AV % da ROL 2025
A6: Receita operacional líquida | B6: =SUM(B7:B13) -> 26116856 | C6: =SUM(C7:C13) -> 22651036 | D6: =B6-C6 -> 3465820 | E6: =IF(C6=0,"",D6/ABS(C6)) -> 0.15300934 | F6: =B6/B$6 -> 1
A7: Fornecimento de energia a consumidores finais | B7: 7961249 | C7: 8454990 | D7: =B7-C7 -> -493741 | E7: =IF(C7=0,"",D7/ABS(C7)) -> -0.058396403 | F7: =B7/B$6 -> 0.30483183
A8: Suprimento de energia a distribuidoras | B8: 4756273 | C8: 3120628 | D8: =B8-C8 -> 1635645 | E8: =IF(C8=0,"",D8/ABS(C8)) -> 0.52413969 | F8: =B8/B$6 -> 0.18211507
A9: Disponibilidade da rede elétrica (TUSD/TUST) | B9: 6974666 | C9: 7048036 | D9: =B9-C9 -> -73370 | E9: =IF(C9=0,"",D9/ABS(C9)) -> -0.010409992 | F9: =B9/B$6 -> 0.26705611
A10: Receita de construção | B10: 3303150 | C10: 2550809 | D10: =B10-C10 -> 752341 | E10: =IF(C10=0,"",D10/ABS(C10)) -> 0.29494211 | F10: =B10/B$6 -> 0.12647579
A11: Valor justo do ativo indenizável da concessão (VNR) | B11: 161244 | C11: 82424 | D11: =B11-C11 -> 78820 | E11: =IF(C11=0,"",D11/ABS(C11)) -> 0.95627487 | F11: =B11/B$6 -> 0.0061739438
A12: Resultado de ativos e passivos financeiros setoriais | B12: 2348143 | C12: 838280 | D12: =B12-C12 -> 1509863 | E12: =IF(C12=0,"",D12/ABS(C12)) -> 1.801144 | F12: =B12/B$6 -> 0.089909099
A13: Outras receitas operacionais | B13: 612131 | C13: 555869 | D13: =B13-C13 -> 56262 | E13: =IF(C13=0,"",D13/ABS(C13)) -> 0.10121449 | F13: =B13/B$6 -> 0.023438158
A14: Custos e despesas operacionais | B14: =SUM(B15:B24) -> -21311842 | C14: =SUM(C15:C24) -> -18867990 | D14: =B14-C14 -> -2443852 | E14: =IF(C14=0,"",D14/ABS(C14)) -> -0.12952371 | F14: =B14/B$6 -> -0.81601867
A15: Energia elétrica comprada para revenda | B15: -11110778 | C15: -8924895 | D15: =B15-C15 -> -2185883 | E15: =IF(C15=0,"",D15/ABS(C15)) -> -0.24491974 | F15: =B15/B$6 -> -0.42542556
A16: Encargos de uso da rede elétrica | B16: -2755534 | C16: -2865490 | D16: =B16-C16 -> 109956 | E16: =IF(C16=0,"",D16/ABS(C16)) -> 0.038372495 | F16: =B16/B$6 -> -0.10550788
A17: Pessoal e administradores | B17: -960788 | C17: -1081797 | D17: =B17-C17 -> 121009 | E17: =IF(C17=0,"",D17/ABS(C17)) -> 0.11185925 | F17: =B17/B$6 -> -0.036788042
A18: Planos previdenciário e assistencial | B18: -234547 | C18: -259352 | D18: =B18-C18 -> 24805 | E18: =IF(C18=0,"",D18/ABS(C18)) -> 0.095642216 | F18: =B18/B$6 -> -0.0089806752
A19: Material | B19: -108061 | C19: -86882 | D19: =B19-C19 -> -21179 | E19: =IF(C19=0,"",D19/ABS(C19)) -> -0.24376741 | F19: =B19/B$6 -> -0.004137596
A20: Serviços de terceiros | B20: -1192282 | C20: -1074308 | D20: =B20-C20 -> -117974 | E20: =IF(C20=0,"",D20/ABS(C20)) -> -0.10981395 | F20: =B20/B$6 -> -0.04565182
A21: Depreciação e amortização | B21: -1481886 | C21: -1465478 | D21: =B21-C21 -> -16408 | E21: =IF(C21=0,"",D21/ABS(C21)) -> -0.011196347 | F21: =B21/B$6 -> -0.056740597
A22: Provisões e reversões | B22: -270787 | C22: -345102 | D22: =B22-C22 -> 74315 | E22: =IF(C22=0,"",D22/ABS(C22)) -> 0.21534213 | F22: =B22/B$6 -> -0.010368285
A23: Custo de construção | B23: -3272763 | C23: -2522908 | D23: =B23-C23 -> -749855 | E23: =IF(C23=0,"",D23/ABS(C23)) -> -0.29721853 | F23: =B23/B$6 -> -0.12531229
A24: Outros custos e despesas | B24: 75584 | C24: -241778 | D24: =B24-C24 -> 317362 | E24: =IF(C24=0,"",D24/ABS(C24)) -> 1.3126174 | F24: =B24/B$6 -> 0.0028940696
A25: Resultado de equivalência patrimonial | B25: 239997 | C25: 281202 | D25: =B25-C25 -> -41205 | E25: =IF(C25=0,"",D25/ABS(C25)) -> -0.14653167 | F25: =B25/B$6 -> 0.0091893527
A26: Lucro antes do resultado financeiro e dos tributos | B26: =B6+B14+B25 -> 5045011 | C26: =C6+C14+C25 -> 4064248 | D26: =B26-C26 -> 980763 | E26: =IF(C26=0,"",D26/ABS(C26)) -> 0.24131475 | F26: =B26/B$6 -> 0.19317069
A27: Resultado financeiro | B27: =B28+B29 -> -1798352 | C27: =C28+C29 -> -1157014 | D27: =B27-C27 -> -641338 | E27: =IF(C27=0,"",D27/ABS(C27)) -> -0.55430444 | F27: =B27/B$6 -> -0.068857905
A28: Receitas financeiras | B28: 1343658 | C28: 1184779 | D28: =B28-C28 -> 158879 | E28: =IF(C28=0,"",D28/ABS(C28)) -> 0.13410011 | F28: =B28/B$6 -> 0.051447923
A29: Despesas financeiras | B29: -3142010 | C29: -2341793 | D29: =B29-C29 -> -800217 | E29: =IF(C29=0,"",D29/ABS(C29)) -> -0.34171124 | F29: =B29/B$6 -> -0.12030583
A30: Lucro antes do IR e da CSLL | B30: =B26+B27 -> 3246659 | C30: =C26+C27 -> 2907234 | D30: =B30-C30 -> 339425 | E30: =IF(C30=0,"",D30/ABS(C30)) -> 0.11675187 | F30: =B30/B$6 -> 0.12431278
A31: IR e CSLL (correntes e diferidos) | B31: -577618 | C31: -599435 | D31: =B31-C31 -> 21817 | E31: =IF(C31=0,"",D31/ABS(C31)) -> 0.03639594 | F31: =B31/B$6 -> -0.022116674
A32: Lucro líquido das operações continuadas | B32: =B30+B31 -> 2669041 | C32: =C30+C31 -> 2307799 | D32: =B32-C32 -> 361242 | E32: =IF(C32=0,"",D32/ABS(C32)) -> 0.15653096 | F32: =B32/B$6 -> 0.10219611
A33: Lucro líquido das operações descontinuadas | B33: 18898 | C33: 491571 | D33: =B33-C33 -> -472673 | E33: =IF(C33=0,"",D33/ABS(C33)) -> -0.96155591 | F33: =B33/B$6 -> 0.00072359399
A34: Lucro líquido do exercício | B34: =B32+B33 -> 2687939 | C34: =C32+C33 -> 2799370 | D34: =B34-C34 -> -111431 | E34: =IF(C34=0,"",D34/ABS(C34)) -> -0.039805742 | F34: =B34/B$6 -> 0.1029197
A36: Checagem: lucro líquido continuado publicado (2.669.041 / 2.307.799) | B36: =IF(B32=2669041,"Confere","DIFERENÇA") -> Confere | C36: =IF(C32=2307799,"Confere","DIFERENÇA") -> Confere
A37: EBITDA publicado (R$ mil) | B37: 6526897 | C37: 5529726
A38: EBITDA recalculado = EBIT + depreciação e amortização (diferença = itens de ajuste da companhia) | B38: =B26-B21 -> 6526897 | C38: =C26-C21 -> 5529726
A39: Diferença (EBITDA publicado - recalculado): zero indica que o EBITDA publicado reconcilia com EBIT + D&A | B39: =B37-B38 -> 0 | C39: =C37-C38 -> 0

Sheet Indicadores
A1: Indicadores analíticos - PT 520 / PT 570
A2: COPEL - exercício 2025 | Preparadora: matrícula 232025417 | Data: 24/10/2026 | Revisão: ____________ (campo não preenchido - sem revisão de terceiros)
A4: Indicador | B4: 2025 | C4: 2024 | D4: Fórmula / leitura
A5: Liquidez corrente (AC / PC) | B5: =BP!B23/BP!B68 -> 0.98366861 | C5: =BP!C23/BP!C68 -> 1.2610065 | D5: Abaixo de 1,0 em 2025 - ver PT 570.
A6: Endividamento bruto (empréstimos + debêntures) | B6: =BP!B55+BP!B56+BP!B75+BP!B76 -> 20015343 | C6: =BP!C55+BP!C56+BP!C75+BP!C76 -> 17246159 | D6: R$ mil. A companhia informa dívida bruta de R$ 20.038,9 mi (inclui efeito de swap).
A7: Dívida bruta / PL | B7: =B6/BP!B99 -> 0.86676607 | C7: =C6/BP!C99 -> 0.67270752
A8: Margem EBITDA (EBITDA / ROL) | B8: =DRE!B37/DRE!B6 -> 0.24991128 | C8: =DRE!C37/DRE!C6 -> 0.24412685 | D8: Release informa 25,0% e 24,4%.
A9: Margem líquida continuada | B9: =DRE!B32/DRE!B6 -> 0.10219611 | C9: =DRE!C32/DRE!C6 -> 0.10188492
A10: ROE simples (LL continuado / PL final) | B10: =DRE!B32/BP!B99 -> 0.11558304 | C10: =DRE!C32/BP!C99 -> 0.090018522 | D10: Release usa PL médio/critério próprio (10,5%).
A11: Prazo médio de recebimento (clientes CP+LP / ROL x 365) | B11: =(BP!B10+BP!B28)/DRE!B6*365 -> 62.37536 | C11: =(BP!C10+BP!C28)/DRE!C6*365 -> 65.727322 | D11: Dias. ROL é líquida de tributos: indicador aproximado.
A12: Intangível / ativo total | B12: =BP!B44/BP!B48 -> 0.31791413 | C12: =BP!C44/BP!C48 -> 0.28968989 | D12: Conta de maior saldo do ativo (PT BS-01).
A13: Amortização+depreciação / (imobilizado+intangível) inicial | B13: =-DRE!B21/(BP!C43+BP!C44) -> 0.058944626 | D13: Taxa média implícita - comparação com taxas regulatórias.
A14: Provisões para litígios: variação % | B14: =(BP!B85/BP!C85)-1 -> 1.0215617 | D14: Quase dobrou (+102%) - risco significativo (PT 315.2).

Sheet Materialidade
A1: Materialidade - PT 320 (NBC TA 320 (R1), itens 10, 11 e 14)
A2: COPEL - exercício 2025 | Preparadora: matrícula 232025417 | Data: 24/10/2026 | Revisão: ____________ (campo não preenchido - sem revisão de terceiros)
A4: Referencial (2025) | B4: Valor (R$ mil) | C4: % aplicado | D4: Resultado (R$ mil) | E4: Comentário
A5: Lucro antes do IR e CSLL - operações continuadas | B5: =DRE!B30 -> 3246659 | C5: 0.05 | D5: =B5*C5 -> 162332.95 | E5: ESCOLHIDO: entidade com fins lucrativos, lucro estável e foco dos usuários (dividendos, payout).
A6: Receita operacional líquida | B6: =DRE!B6 -> 26116856 | C6: 0.005 | D6: =B6*C6 -> 130584.28 | E6: Alternativo: receita inclui repasses (energia comprada, construção) sem margem.
A7: Patrimônio líquido | B7: =BP!B99 -> 23091978 | C7: 0.01 | D7: =B7*C7 -> 230919.78 | E7: Alternativo.
A8: Ativo total | B8: =BP!B48 -> 60414456 | C8: 0.005 | D8: =B8*C8 -> 302072.28 | E8: Alternativo: intensivo em ativos regulados.
A9: EBITDA | B9: =DRE!B37 -> 6526897 | C9: 0.03 | D9: =B9*C9 -> 195806.91 | E9: Alternativo: métrica usada pelo mercado e por covenants.
A12: Materialidade global (MG) - arredondada | B12: =ROUND(D5,0) -> 162333
A13: % para materialidade de execução (ME) | B13: 0.7
A14: Materialidade para execução (ME) | B14: =ROUND(B12*B13,0) -> 113633
A15: % limite de distorção claramente trivial | B15: 0.05
A16: Limite claramente trivial | B16: =ROUND(B12*B15,0) -> 8117
A17: MG em % do lucro líquido continuado | B17: =B12/DRE!B32 -> 0.060820722
A18: MG em % do ativo total | B18: =B12/BP!B48 -> 0.0026869894
A20: Materialidade específica (menor) - remuneração do pessoal-chave e partes relacionadas: avaliação qualitativa, qualquer distorção é relevante por natureza (NBC TA 320, item 10).
A21: Checagem com o código Python (02_testes_auditoria.py): MG / ME / trivial | B21: 162333 | C21: 113633 | D21: 8117 | E21: =IF(AND(B21=B12,C21=B14,D21=B16),"Planilha = código","DIVERGÊNCIA") -> Planilha = código

Sheet Contas_Significativas
A1: Contas acima da materialidade de execução - PT 315.2 / PT 330
A2: COPEL - exercício 2025 | Preparadora: matrícula 232025417 | Data: 24/10/2026 | Revisão: ____________ (campo não preenchido - sem revisão de terceiros)
A4: Rubrica | B4: 31/12/2025 | C4: |Var| R$ | D4: Classificação | E4: Grupo
A5: Caixa e equivalentes de caixa | B5: =BP!B7 -> 3130363 | C5: =ABS(BP!B7-BP!C7) -> 1031576 | D5: =IF(OR(ABS(B5)>=Materialidade!$B$14,C5>=Materialidade!$B$14),"Significativa (>= ME)","Abaixo da ME") -> Significativa (>= ME) | E5: Ativo circulante
A6: Títulos e valores mobiliários | B6: =BP!B8 -> 895 | C6: =ABS(BP!B8-BP!C8) -> 272 | D6: =IF(OR(ABS(B6)>=Materialidade!$B$14,C6>=Materialidade!$B$14),"Significativa (>= ME)","Abaixo da ME") -> Abaixo da ME | E6: Ativo circulante
A7: Cauções e depósitos vinculados | B7: =BP!B9 -> 9 | C7: =ABS(BP!B9-BP!C9) -> 0 | D7: =IF(OR(ABS(B7)>=Materialidade!$B$14,C7>=Materialidade!$B$14),"Significativa (>= ME)","Abaixo da ME") -> Abaixo da ME | E7: Ativo circulante
A8: Clientes | B8: =BP!B10 -> 4300957 | C8: =ABS(BP!B10-BP!C10) -> 338255 | D8: =IF(OR(ABS(B8)>=Materialidade!$B$14,C8>=Materialidade!$B$14),"Significativa (>= ME)","Abaixo da ME") -> Significativa (>= ME) | E8: Ativo circulante
A9: Dividendos a receber | B9: =BP!B11 -> 141297 | C9: =ABS(BP!B11-BP!C11) -> 59019 | D9: =IF(OR(ABS(B9)>=Materialidade!$B$14,C9>=Materialidade!$B$14),"Significativa (>= ME)","Abaixo da ME") -> Significativa (>= ME) | E9: Ativo circulante
A10: Ativos financeiros setoriais | B10: =BP!B12 -> 400463 | C10: =ABS(BP!B12-BP!C12) -> 400463 | D10: =IF(OR(ABS(B10)>=Materialidade!$B$14,C10>=Materialidade!$B$14),"Significativa (>= ME)","Abaixo da ME") -> Significativa (>= ME) | E10: Ativo circulante
A11: Contas a receber vinculadas à concessão | B11: =BP!B13 -> 12867 | C11: =ABS(BP!B13-BP!C13) -> 2258 | D11: =IF(OR(ABS(B11)>=Materialidade!$B$14,C11>=Materialidade!$B$14),"Significativa (>= ME)","Abaixo da ME") -> Abaixo da ME | E11: Ativo circulante
A12: Ativos de contrato | B12: =BP!B14 -> 392594 | C12: =ABS(BP!B14-BP!C14) -> 108698 | D12: =IF(OR(ABS(B12)>=Materialidade!$B$14,C12>=Materialidade!$B$14),"Significativa (>= ME)","Abaixo da ME") -> Significativa (>= ME) | E12: Ativo circulante
A13: Valor justo nas operações de compra e venda de energia | B13: =BP!B15 -> 263645 | C13: =ABS(BP!B15-BP!C15) -> 46295 | D13: =IF(OR(ABS(B13)>=Materialidade!$B$14,C13>=Materialidade!$B$14),"Significativa (>= ME)","Abaixo da ME") -> Significativa (>= ME) | E13: Ativo circulante
A14: Outros créditos | B14: =BP!B16 -> 1050086 | C14: =ABS(BP!B16-BP!C16) -> 100412 | D14: =IF(OR(ABS(B14)>=Materialidade!$B$14,C14>=Materialidade!$B$14),"Significativa (>= ME)","Abaixo da ME") -> Significativa (>= ME) | E14: Ativo circulante
A15: Estoques | B15: =BP!B17 -> 173398 | C15: =ABS(BP!B17-BP!C17) -> 37074 | D15: =IF(OR(ABS(B15)>=Materialidade!$B$14,C15>=Materialidade!$B$14),"Significativa (>= ME)","Abaixo da ME") -> Significativa (>= ME) | E15: Ativo circulante
A16: Imposto de renda e contribuição social a recuperar | B16: =BP!B18 -> 502825 | C16: =ABS(BP!B18-BP!C18) -> 206697 | D16: =IF(OR(ABS(B16)>=Materialidade!$B$14,C16>=Materialidade!$B$14),"Significativa (>= ME)","Abaixo da ME") -> Significativa (>= ME) | E16: Ativo circulante
... A20: Ativos classificados como mantidos para venda | B20: =BP!B22 -> 25177 | C20: =ABS(BP!B22-BP!C22) -> 1856649 | D20: =IF(OR(ABS(B20)>=Materialidade!$B$14,C20>=Materialidade!$B$14),"Significativa (>= ME)","Abaixo da ME") -> Significativa (>= ME) | E20: Ativo circulante
A21: Títulos e valores mobiliários | B21: =BP!B26 -> 690886 | C21: =ABS(BP!B26-BP!C26) -> 161801 | D21: =IF(OR(ABS(B21)>=Materialidade!$B$14,C21>=Materialidade!$B$14),"Significativa (>= ME)","Abaixo da ME") -> Significativa (>= ME) | E21: Realizável LP
A22: Outros investimentos temporários | B22: =BP!B27 -> 30627 | C22: =ABS(BP!B27-BP!C27) -> 24 | D22: =IF(OR(ABS(B22)>=Materialidade!$B$14,C22>=Materialidade!$B$14),"Significativa (>= ME)","Abaixo da ME") -> Abaixo da ME | E22: Realizável LP
A23: Clientes | B23: =BP!B28 -> 162189 | C23: =ABS(BP!B28-BP!C28) -> 46009 | D23: =IF(OR(ABS(B23)>=Materialidade!$B$14,C23>=Materialidade!$B$14),"Significativa (>= ME)","Abaixo da ME") -> Significativa (>= ME) | E23: Realizável LP
A24: Depósitos judiciais | B24: =BP!B29 -> 373949 | C24: =ABS(BP!B29-BP!C29) -> 20415 | D24: =IF(OR(ABS(B24)>=Materialidade!$B$14,C24>=Materialidade!$B$14),"Significativa (>= ME)","Abaixo da ME") -> Significativa (>= ME) | E24: Realizável LP
A25: Ativos financeiros setoriais | B25: =BP!B30 -> 400463 | C25: =ABS(BP!B30-BP!C30) -> 400463 | D25: =IF(OR(ABS(B25)>=Materialidade!$B$14,C25>=Materialidade!$B$14),"Significativa (>= ME)","Abaixo da ME") -> Significativa (>= ME) | E25: Realizável LP
A26: Contas a receber vinculadas à concessão | B26: =BP!B31 -> 4590579 | C26: =ABS(BP!B31-BP!C31) -> 1093228 | D26: =IF(OR(ABS(B26)>=Materialidade!$B$14,C26>=Materialidade!$B$14),"Significativa (>= ME)","Abaixo da ME") -> Significativa (>= ME) | E26: Realizável LP
A27: Ativos de contrato | B27: =BP!B32 -> 9202412 | C27: =ABS(BP!B32-BP!C32) -> 2275402 | D27: =IF(OR(ABS(B27)>=Materialidade!$B$14,C27>=Materialidade!$B$14),"Significativa (>= ME)","Abaixo da ME") -> Significativa (>= ME) | E27: Realizável LP
A28: Valor justo nas operações de compra e venda de energia | B28: =BP!B33 -> 597856 | C28: =ABS(BP!B33-BP!C33) -> 117918 | D28: =IF(OR(ABS(B28)>=Materialidade!$B$14,C28>=Materialidade!$B$14),"Significativa (>= ME)","Abaixo da ME") -> Significativa (>= ME) | E28: Realizável LP
A29: Outros créditos | B29: =BP!B34 -> 794296 | C29: =ABS(BP!B34-BP!C34) -> 112450 | D29: =IF(OR(ABS(B29)>=Materialidade!$B$14,C29>=Materialidade!$B$14),"Significativa (>= ME)","Abaixo da ME") -> Significativa (>= ME) | E29: Realizável LP
A30: Imposto de renda e contribuição social a recuperar | B30: =BP!B35 -> 102589 | C30: =ABS(BP!B35-BP!C35) -> 61454 | D30: =IF(OR(ABS(B30)>=Materialidade!$B$14,C30>=Materialidade!$B$14),"Significativa (>= ME)","Abaixo da ME") -> Abaixo da ME | E30: Realizável LP
A31: Imposto de renda e contribuição social diferidos | B31: =BP!B36 -> 991404 | C31: =ABS(BP!B36-BP!C36) -> 182771 | D31: =IF(OR(ABS(B31)>=Materialidade!$B$14,C31>=Materialidade!$B$14),"Significativa (>= ME)","Abaixo da ME") -> Significativa (>= ME) | E31: Realizável LP
A32: Outros tributos a recuperar | B32: =BP!B37 -> 1127582 | C32: =ABS(BP!B37-BP!C37) -> 192944 | D32: =IF(OR(ABS(B32)>=Materialidade!$B$14,C32>=Materialidade!$B$14),"Significativa (>= ME)","Abaixo da ME") -> Significativa (>= ME) | E32: Realizável LP
A33: Despesas antecipadas | B33: =BP!B38 -> 507 | C33: =ABS(BP!B38-BP!C38) -> 507 | D33: =IF(OR(ABS(B33)>=Materialidade!$B$14,C33>=Materialidade!$B$14),"Significativa (>= ME)","Abaixo da ME") -> Abaixo da ME | E33: Realizável LP
A34: Investimentos | B34: =BP!B42 -> 2849002 | C34: =ABS(BP!B42-BP!C42) -> 728935 | D34: =IF(OR(ABS(B34)>=Materialidade!$B$14,C34>=Materialidade!$B$14),"Significativa (>= ME)","Abaixo da ME") -> Significativa (>= ME) | E34: Ativo não circulante
A35: Imobilizado | B35: =BP!B43 -> 8145552 | C35: =ABS(BP!B43-BP!C43) -> 371145 | D35: =IF(OR(ABS(B35)>=Materialidade!$B$14,C35>=Materialidade!$B$14),"Significativa (>= ME)","Abaixo da ME") -> Significativa (>= ME) | E35: Ativo não circulante
A36: Intangível | B36: =BP!B44 -> 19206609 | C36: =ABS(BP!B44-BP!C44) -> 2582999 | D36: =IF(OR(ABS(B36)>=Materialidade!$B$14,C36>=Materialidade!$B$14),"Significativa (>= ME)","Abaixo da ME") -> Significativa (>= ME) | E36: Ativo não circulante
A37: Direito de uso de ativos | B37: =BP!B45 -> 266300 | C37: =ABS(BP!B45-BP!C45) -> 42683 | D37: =IF(OR(ABS(B37)>=Materialidade!$B$14,C37>=Materialidade!$B$14),"Significativa (>= ME)","Abaixo da ME") -> Significativa (>= ME) | E37: Ativo não circulante
A38: Obrigações sociais e trabalhistas | B38: =BP!B51 -> 310773 | C38: =ABS(BP!B51-BP!C51) -> 100329 | D38: =IF(OR(ABS(B38)>=Materialidade!$B$14,C38>=Materialidade!$B$14),"Significativa (>= ME)","Abaixo da ME") -> Significativa (>= ME) | E38: Passivo circulante
A39: Fornecedores | B39: =BP!B52 -> 3059667 | C39: =ABS(BP!B52-BP!C52) -> 735244 | D39: =IF(OR(ABS(B39)>=Materialidade!$B$14,C39>=Materialidade!$B$14),"Significativa (>= ME)","Abaixo da ME") -> Significativa (>= ME) | E39: Passivo circulante
A40: Imposto de renda e contribuição social a recolher | B40: =BP!B53 -> 81875 | C40: =ABS(BP!B53-BP!C53) -> 1607 | D40: =IF(OR(ABS(B40)>=Materialidade!$B$14,C40>=Materialidade!$B$14),"Significativa (>= ME)","Abaixo da ME") -> Abaixo da ME | E40: Passivo circulante
A41: Outras obrigações fiscais | B41: =BP!B54 -> 677273 | C41: =ABS(BP!B54-BP!C54) -> 374928 | D41: =IF(OR(ABS(B41)>=Materialidade!$B$14,C41>=Materialidade!$B$14),"Significativa (>= ME)","Abaixo da ME") -> Significativa (>= ME) | E41: Passivo circulante
A42: Empréstimos e financiamentos | B42: =BP!B55 -> 217827 | C42: =ABS(BP!B55-BP!C55) -> 1013378 | D42: =IF(OR(ABS(B42)>=Materialidade!$B$14,C42>=Materialidade!$B$14),"Significativa (>= ME)","Abaixo da ME") -> Significativa (>= ME) | E42: Passivo circulante
A43: Debêntures | B43: =BP!B56 -> 1850538 | C43: =ABS(BP!B56-BP!C56) -> 174572 | D43: =IF(OR(ABS(B43)>=Materialidade!$B$14,C43>=Materialidade!$B$14),"Significativa (>= ME)","Abaixo da ME") -> Significativa (>= ME) | E43: Passivo circulante
A44: Dividendos mínimos obrigatórios a pagar | B44: =BP!B57 -> 2325889 | C44: =ABS(BP!B57-BP!C57) -> 2322011 | D44: =IF(OR(ABS(B44)>=Materialidade!$B$14,C44>=Materialidade!$B$14),"Significativa (>= ME)","Abaixo da ME") -> Significativa (>= ME) | E44: Passivo circulante
...

Sheet Conciliacao_Intangivel
A1: Conciliação da base SINTÉTICA com o saldo contábil - PT BS-04
A2: COPEL - exercício 2025 | Preparadora: matrícula 232025417 | Data: 24/10/2026 | Revisão: ____________ (campo não preenchido - sem revisão de terceiros)
A3: DADOS SINTÉTICOS: totais por subconta extraídos de resultados/resultados_testes.json (T01). Categorias da NE 16 (F17) e subtotal GeT (F15) são reais; divisão interna da geração é hipótese (PT BS-02).
A5: Subconta | B5: Descrição | C5: Linhas | D5: Custo (R$) | E5: Amortização (R$) | F5: Valor líquido (R$)
A6: INT-AUO | B6: Direito de autorização - demais empresas - por diferença F17-F15 | C6: 1 | D6: 9589772.9 | E6: 1855772.9 | F6: 7734000
A7: INT-BON | B7: Bônus de outorga - usinas renovadas | C7: 3 | D7: 4.3531002e+09 | E7: 1.6130021e+08 | F7: 4191800000
A8: INT-CNB | B8: Combinação de negócios (UHE Mauá) | C8: 2 | D8: 7.1753678e+08 | E8: 17536776 | F8: 700000000
A9: INT-DIS | B9: Contrato de concessão - distribuição (real: F17) | C9: 512150 | D9: 1.6953261e+10 | E9: 5.0860267e+09 | F9: 11868128000
A10: INT-EOL | B10: Direito de concessão e autorização / ágio técnico - eólicas (real: F15) | C10: 42 | D10: 1.6831915e+09 | E10: 2.8114848e+08 | F10: 1402043000
A11: INT-GSF | B11: Repactuação do risco hidrológico (GSF) | C11: 9 | D11: 3.0189737e+08 | E11: 41897375 | F11: 260000000
A12: INT-SGT | B12: Softwares e outros - Copel GeT (real: F15) | C12: 2000 | D12: 1.5864668e+08 | E12: 81870675 | F12: 76776000
A13: INT-SOF | B13: Softwares e outros - demais empresas | C13: 5950 | D13: 41790181 | E13: 21219181 | F13: 20571000
A14: INT-UBE | B14: Geração fora da Copel GeT (Elejor e outras) - por diferença F17-F15 | C14: 2 | D14: 3.7044496e+08 | E14: 2.1088796e+08 | F14: 159557000
A15: INT-UBP | B15: Uso do bem público (UBP) | C15: 6 | D15: 8.2675889e+08 | E15: 3.0675889e+08 | F15: 520000000
B16: Total da base sintética | C16: =SUM(C6:C15) -> 520165 | D16: =SUM(D6:D15) -> 2.5416217e+10 | E16: =SUM(E6:E15) -> 6.210502e+09 | F16: =SUM(F6:F15) -> 19206609000
B17: Saldo contábil - Intangível consolidado 31/12/2025 (R$ mil x 1.000) | F17: =BP!B44*1000 -> 19206609000
B18: Diferença (base - contábil) | F18: =ROUND(F16-F17,2) -> 0
B19: Conclusão | F19: =IF(F18=0,"Conciliado sem diferença","Investigar diferença") -> Conciliado sem diferença
B21: Âncora verificável: Intangível da controlada F.D.A. (F07, p. 8) alocado ao registro de Foz do Areia na base (R$ mil) | F21: 1849570
B22: Variação do intangível no exercício (R$ mil) - movimentação a obter na nota explicativa (P) | F22: =BP!B44-BP!C44 -> 2582999
B23: Adições ao intangível na DFC (R$ mil) - a diferença indica transferências de ativos de contrato e combinação de negócios (sem efeito caixa) | F23: 43788
B24: Subtotal do segmento Copel GeT na base (R$) | F24: 7150619000
B25: Intangível consolidado da Copel GeT em 31/12/2025 - F15, ITR 1T26, NE 15, p. 21 (R$) | F25: 7150619000
B26: Diferença (base - F15) | F26: =ROUND(F24-F25,2) -> 0
A29: Categoria NE 16 | D29: Base (R$) | E29: NE 16 - F17 (R$) | F29: Diferença
A30: Distribuição | D30: 11868128000 | E30: 11868128000 | F30: =ROUND(D30-E30,2) -> 0
A31: Geração | D31: 5831357000 | E31: 5831357000 | F31: =ROUND(D31-E31,2) -> 0
A32: Direito de concessão e autorização | D32: 1409777000 | E32: 1409777000 | F32: =ROUND(D32-E32,2) -> 0
A33: Outros intangíveis | D33: 97347000 | E33: 97347000 | F33: =ROUND(D33-E33,2) -> 0
A36: Movimentação real do intangível 2025 - F17, NE 16, p. 91 (R$ mil)
A37: Saldo em 31.12.2024 | F37: 16623610
A38: Efeito de combinação de negócios | F38: 731591
A39: Outorga Aneel - uso do bem público | F39: -1728
A40: Aquisições | F40: 43788
A41: Quotas de amortização | F41: -930256
A42: Transferências de ativos de contrato | F42: 2901548
A43: Baixas | F43: -148017
A44: Reclassificação para mantidos para venda | F44: -13927
A45: Saldo recalculado em 31.12.2025 | F45: =SUM(F37:F44) -> 19206609
A46: Confere com o balanço? | F46: =IF(F45=BP!B44,"Confere","DIFERENÇA") -> Confere

Sheet MUS_Parametros
A1: Amostragem por unidade monetária - parâmetros (SIMULADO) - PT 530
A2: COPEL - exercício 2025 | Preparadora: matrícula 232025417 | Data: 24/10/2026 | Revisão: ____________ (campo não preenchido - sem revisão de terceiros)
A5: Valor contábil da população com saldo positivo (R$) | B5: 1.9206708e+10 | C5: Base sintética, T11.
A6: Distorção tolerável (R$) = ME x 1.000 | B6: =Materialidade!B14*1000 -> 113633000 | C6: Vinculada à materialidade de execução.
A7: % distorção esperada sobre a tolerável | B7: 0.1 | C7: Premissa (fill amarelo).
A8: Distorção esperada (R$) | B8: =B6*B7 -> 11363300
A9: Fator de confiabilidade (95%, zero erros) | B9: 2.9957 | C9: Poisson.
A10: Fator de expansão | B10: 1.6 | C10: Tabela AICPA, 95%.
A11: Tamanho da amostra n | B11: =ROUNDUP(B5*B9/(B6-B8*B10),0) -> 603
A12: Intervalo amostral J (R$) | B12: =B5/B11 -> 31851920
A13: Início aleatório (R$) - semente 232025417 | B13: 15663335
A14: Checagem: n do código Python | B14: 603
A15: Conferência | B15: =IF(B11=B14,"Planilha = código","DIVERGÊNCIA") -> Planilha = código
A16: Itens selecionados únicos (há itens maiores que J) | B16: 437
A17: Itens-chave (valor >= J) - 100% examinados | B17: 37
A18: Registros com valor <= 0 excluídos (testados por CAAT, T02) | B18: 20014 | C18: Inclui bens totalmente amortizados (valor zero) e 40 negativos.

Sheet MUS_Amostra
A1: Itens selecionados - inspeção SIMULADA (valor auditado vem do gabarito)
A2: COPEL - exercício 2025 | Preparadora: matrícula 232025417 | Data: 24/10/2026 | Revisão: ____________ (campo não preenchido - sem revisão de terceiros)
A4: id_registro (SINT) | B4: Subconta | C4: Tipo de bem | D4: Status | E4: Valor contábil (R$) | F4: Item-chave | G4: Valor auditado simulado (R$) | H4: Distorção (R$) | I4: Contaminação
A5: SINT-0000521 | B5: INT-DIS | C5: Trecho de linha de distribuição AT (138 kV) | D5: Em serviço | E5: 413420.4 | F5: =IF(E5>=MUS_Parametros!$B$12,"SIM","NÃO") -> NÃO | G5: 413420.4 | H5: =E5-G5 -> 0 | I5: =IF(F5="SIM","",H5/E5) -> 0
A6: SINT-0000761 | B6: INT-BON | C6: UHE Gov. Bento Munhoz da Rocha Netto (Foz do Areia) - F.D.A. | D6: Em serviço | E6: 1849570000 | F6: =IF(E6>=MUS_Parametros!$B$12,"SIM","NÃO") -> SIM | G6: 1849570000 | H6: =E6-G6 -> 0 | I6: =IF(F6="SIM","",H6/E6)
A7: SINT-0001458 | B7: INT-DIS | C7: Trecho de linha de distribuição AT (138 kV) | D7: Em serviço | E7: 468861.08 | F7: =IF(E7>=MUS_Parametros!$B$12,"SIM","NÃO") -> NÃO | G7: 468861.08 | H7: =E7-G7 -> 0 | I7: =IF(F7="SIM","",H7/E7) -> 0
A8: SINT-0002294 | B8: INT-EOL | C8: Autorização eólica - Parque 29 (sintético) | D8: Em serviço | E8: 47687003 | F8: =IF(E8>=MUS_Parametros!$B$12,"SIM","NÃO") -> SIM | G8: 47687003 | H8: =E8-G8 -> 0 | I8: =IF(F8="SIM","",H8/E8)
A9: SINT-0003873 | B9: INT-DIS | C9: Trecho de rede trifásica rural (MT) | D9: Em serviço | E9: 69254.51 | F9: =IF(E9>=MUS_Parametros!$B$12,"SIM","NÃO") -> NÃO | G9: 69254.51 | H9: =E9-G9 -> 0 | I9: =IF(F9="SIM","",H9/E9) -> 0
A10: SINT-0004357 | B10: INT-DIS | C10: Trecho de rede trifásica rural (MT) | D10: Em serviço | E10: 104887.4 | F10: =IF(E10>=MUS_Parametros!$B$12,"SIM","NÃO") -> NÃO | G10: 104887.4 | H10: =E10-G10 -> 0 | I10: =IF(F10="SIM","",H10/E10) -> 0
A11: SINT-0005780 | B11: INT-DIS | C11: Edificação operacional | D11: Em serviço | E11: 769016.08 | F11: =IF(E11>=MUS_Parametros!$B$12,"SIM","NÃO") -> NÃO | G11: 769016.08 | H11: =E11-G11 -> 0 | I11: =IF(F11="SIM","",H11/E11) -> 0
A12: SINT-0006857 | B12: INT-DIS | C12: Religador / chave automatizada | D12: Em serviço | E12: 50275.68 | F12: =IF(E12>=MUS_Parametros!$B$12,"SIM","NÃO") -> NÃO | G12: 50275.68 | H12: =E12-G12 -> 0 | I12: =IF(F12="SIM","",H12/E12) -> 0
A13: SINT-0008093 | B13: INT-DIS | C13: Equipamento de subestação de distribuição | D13: Em serviço | E13: 1993512.9 | F13: =IF(E13>=MUS_Parametros!$B$12,"SIM","NÃO") -> NÃO | G13: 1993512.9 | H13: =E13-G13 -> 0 | I13: =IF(F13="SIM","",H13/E13) -> 0
A14: SINT-0009736 | B14: INT-DIS | C14: Equipamento de subestação de distribuição | D14: Em serviço | E14: 1268180.6 | F14: =IF(E14>=MUS_Parametros!$B$12,"SIM","NÃO") -> NÃO | G14: 1268180.6 | H14: =E14-G14 -> 0 | I14: =IF(F14="SIM","",H14/E14) -> 0
A15: SINT-0010187 | B15: INT-CNB | C15: Direito de concessão - UHE Mauá (mais-valia alocada) | D15: Em serviço | E15: 210000000 | F15: =IF(E15>=MUS_Parametros!$B$12,"SIM","NÃO") -> SIM | G15: 210000000 | H15: =E15-G15 -> 0 | I15: =IF(F15="SIM","",H15/E15)
A16: SINT-0010279 | B16: INT-DIS | C16: Trecho de linha de distribuição AT (138 kV) | D16: Em serviço | E16: 251567.62 | F16: =IF(E16>=MUS_Parametros!$B$12,"SIM","NÃO") -> NÃO | G16: 251567.62 | H16: =E16-G16 -> 0 | I16: =IF(F16="SIM","",H16/E16) -> 0
... A441: SINT-0519525 | B441: INT-DIS | C441: Trecho de linha de distribuição AT (138 kV) | D441: Em serviço | E441: 2463240.9 | F441: =IF(E441>=MUS_Parametros!$B$12,"SIM","NÃO") -> NÃO | G441: 2463240.9 | H441: =E441-G441 -> 0 | I441: =IF(F441="SIM","",H441/E441) -> 0

Sheet MUS_Avaliacao
A1: Avaliação da amostra MUS (SIMULADO) - PT 530 / PT 450
A2: COPEL - exercício 2025 | Preparadora: matrícula 232025417 | Data: 24/10/2026 | Revisão: ____________ (campo não preenchido - sem revisão de terceiros)
A4: Fatores de Poisson 95% (k erros)
A5: k = 0 | B5: 2.9957
A6: k = 1 | B6: 4.7439
A7: k = 2 | B7: 6.2958
A8: k = 3 | B8: 7.7537
A9: k = 4 | B9: 9.1535
A10: k = 5 | B10: 10.513
A11: k = 6 | B11: 11.8424
A12: k = 7 | B12: 13.1481
A14: Itens não-chave com distorção (contagem) | B14: =COUNTIFS(MUS_Amostra!F5:F441,"NÃO",MUS_Amostra!H5:H441,">0") -> 2
A15: Soma das contaminações (superavaliação, não-chave) | B15: =SUMIFS(MUS_Amostra!I5:I441,MUS_Amostra!F5:F441,"NÃO",MUS_Amostra!H5:H441,">0") -> 2
A16: Distorção em itens-chave (R$) | B16: =SUMIFS(MUS_Amostra!H5:H441,MUS_Amostra!F5:F441,"SIM") -> 0
A17: Precisão básica = J x fator(0) | B17: =MUS_Parametros!B12*B5 -> 95418798
A18: Distorção projetada = soma contaminações x J + itens-chave | B18: =B15*MUS_Parametros!B12+B16 -> 63703841
A19: Provisão incremental (contaminações = 1,0 ordenadas; fórmula válida para até 7 erros) | B19: =IF(B14=0,0,MUS_Parametros!B12*(INDEX(B5:B12,B14+1)-B5-B14)) -> 41410682
A20: Limite superior de distorção (LSD) | B20: =B17+B18+B19 -> 2.0053332e+08
A21: Distorção tolerável | B21: =MUS_Parametros!B6 -> 113633000
A22: Conclusão (simulação) | B22: =IF(B20<B21,"LSD < tolerável: aceitar","LSD > tolerável: estender testes (100% via CAAT) e propor ajuste") -> LSD > tolerável: estender testes (100% via CAAT) e propor ajuste
A23: Checagem LSD do código Python | B23: 2.0053332e+08 | C23: =IF(ABS(B23-B20)<1,"Planilha = código","DIVERGÊNCIA") -> Planilha = código

Sheet Excecoes
A1: Erros inseridos x exceções identificadas (SIMULADO) - PT BS-06
A2: COPEL - exercício 2025 | Preparadora: matrícula 232025417 | Data: 24/10/2026 | Revisão: ____________ (campo não preenchido - sem revisão de terceiros)
A4: Código | B4: Natureza do erro inserido | C4: Inseridos | D4: Detectados | E4: Taxa | F4: Distorção inserida (R$) | G4: Teste principal
A5: E01 | B5: Registro duplicado | C5: 150 | D5: 150 | E5: =D5/C5 -> 1 | F5: 1467246.5 | G5: T03
A6: E02 | B6: Amortização acumulada > custo (líquido negativo) | C6: 40 | D6: 40 | E6: =D6/C6 -> 1 | F6: -396374.59 | G6: T02
A7: E03 | B7: Capitalização após 31/12/2025 (corte) | C7: 60 | D7: 60 | E7: =D7/C7 -> 1 | F7: 1239096.9 | G7: T04
A8: E04 | B8: Em serviço sem amortização | C8: 80 | D8: 80 | E8: =D8/C8 -> 1 | F8: 644225.01 | G8: T05
A9: E05 | B9: Taxa abaixo da mínima do prazo de concessão | C9: 70 | D9: 70 | E9: =D9/C9 -> 1 | F9: 409618.19 | G9: T06
A10: E06 | B10: ODI/contrato em branco | C10: 50 | D10: 50 | E10: =D10/C10 -> 1 | F10: 0 | G10: T08
A11: E07 | B11: Lançamento manual fictício abaixo da alçada, fim do exercício | C11: 30 | D11: 30 | E11: =D11/C11 -> 1 | F11: 29830693 | G11: T09/T08
A12: E08 | B12: Em curso com amortização | C12: 45 | D12: 45 | E12: =D12/C12 -> 1 | F12: -183716.43 | G12: T07
A13: E09 | B13: Valor líquido diverge de custo - amortização | C13: 55 | D13: 55 | E13: =D13/C13 -> 1 | F13: 893683.96 | G13: T02
B14: Total | C14: =SUM(C5:C13) -> 580 | D14: =SUM(D5:D13) -> 580 | E14: =D14/C14 -> 1 | F14: =SUM(F5:F13) -> 33904472
B15: Falsos positivos (exceções sem erro inserido) | D15: 0

Sheet Distorcoes
A1: Sumário de distorções - PT 450 (NBC TA 450 (R1))
A2: COPEL - exercício 2025 | Preparadora: matrícula 232025417 | Data: 24/10/2026 | Revisão: ____________ (campo não preenchido - sem revisão de terceiros)
A3: Parte A - evidência pública: nenhuma distorção identificada (trabalho sem acesso a registros).
A4: Parte B - SIMULADO: distorções identificadas na base sintética do intangível (CAAT 100%).
A6: Item | B6: Valor (R$ mil) | C6: Referência | D6: Comentário
A7: Distorção factual identificada na base sintética (superavaliação líquida) | B7: =Excecoes!F14/1000 -> 33904.472 | C7: PT BS-06
A8: Limite claramente trivial | B8: =Materialidade!B16 -> 8117
A9: Materialidade para execução | B9: =Materialidade!B14 -> 113633
A10: Materialidade global | B10: =Materialidade!B12 -> 162333
A11: Conclusão quantitativa | B11: =IF(B7<=B8,"Trivial",IF(B7<B9,"Acima do trivial e abaixo da ME: acumular e solicitar correção",IF(B7<B10,"Acima da ME: solicitar correção; avaliar efeito agregado","Relevante"))) -> Acima do trivial e abaixo da ME: acumular e solicitar correção
A12: Aspecto qualitativo: E07 tem natureza de fraude (lançamentos fictícios) - relevante por natureza, comunicar à governança (NBC TA 240/260) independentemente do valor.

Sheet Analiticos
A1: Procedimentos analíticos e reconciliações - PT 520 / PT 540
A2: COPEL - exercício 2025 | Preparadora: matrícula 232025417 | Data: 24/10/2026 | Revisão: ____________ (campo não preenchido - sem revisão de terceiros)
A4: Item | B4: Valor A | C4: Valor B | D4: Resultado / leitura
A5: Provisões para litígios no balanço (R$ mil) x provisão para processos judiciais no 20-F (R$ mi x 1.000) | B5: =BP!B85 -> 1934020 | C5: 1571600 | D5: =B5-C5 -> 362420 | E5: Explicada: a linha inclui contraprestação contingente de R$ 362.465 mil (F17, NE 26, p. 105) - ver linha 12.
A6: Receita de construção x custo de construção (margem ICPC 01) | B6: =DRE!B10 -> 3303150 | C6: =-DRE!B23 -> 3272763 | D6: =B6-C6 -> 30387 | E6: Margem pequena: coerente com reconhecimento a custo + margem.
A7: Resultado de ativos/passivos setoriais (CVA): variação 2025/2024 | B7: =DRE!B12 -> 2348143 | C7: =DRE!C12 -> 838280 | D7: =B7/C7-1 -> 1.801144 | E7: Aumento de 180%: estimativa regulatória - risco significativo.
A8: Energia comprada para revenda: variação | B8: =DRE!B15 -> -11110778 | C8: =DRE!C15 -> -8924895 | D8: =B8/C8-1 -> 0.24491974 | E8: Crescimento compatível com volumes da Copel Com.
A9: Despesas financeiras: variação | B9: =DRE!B29 -> -3142010 | C9: =DRE!C29 -> -2341793 | D9: =B9/C9-1 -> 0.34171124 | E9: Aumento de dívida e Selic 15% (F02, p. 15).
A10: Expectativa de despesa financeira: dívida média x custo médio 13,22% (R$ mil) | B10: =(Indicadores!B6+Indicadores!C6)/2*0.1322 -> 2462985.3 | C10: =-DRE!B29 -> 3142010 | D10: =C10/B10-1 -> 0.27569175 | E10: Despesa registrada vs. expectativa (dívida média x custo nominal informado). Diferença inclui outros itens.
A11: Dividendos mínimos a pagar 31/12/2025 x proventos declarados no 4T25 (R$ mi 1.350 + 1.100) | B11: =BP!B57 -> 2325889 | C11: 2450000 | D11: =B11-C11 -> -124111 | E11: IRRF sobre JCP (R$ 168.009 mil, F17 NE 12.2) explica a direção; resíduo de R$ 43.898 mil em aberto (Expectativas_520).
A12: Diferença de provisões menos contraprestação contingente (F17, NE 26.3) | B12: =D5 -> 362420 | C12: 362465 | D12: =B12-C12 -> -45 | E12: Resíduo de arredondamento (20-F informa R$ milhões com uma casa).
A13: Vencidos líquidos de PECLD (R$ mi, F02 p.5) / clientes CP | B13: 605500 | C13: =BP!B10 -> 4300957 | D13: =B13/C13 -> 0.14078262 | E13: Proporção dos vencidos no saldo de clientes.

Sheet Continuidade
A1: Continuidade operacional - PT 570 (NBC TA 570)
A2: COPEL - exercício 2025 | Preparadora: matrícula 232025417 | Data: 24/10/2026 | Revisão: ____________ (campo não preenchido - sem revisão de terceiros)
A4: Item | B4: R$ milhões | C4: Fonte / leitura
A5: Caixa e aplicações (release, seção 1.7) | B5: 3739 | C5: F01, p. 8
A6: Amortizações de dívida em 2026 | B6: 2068 | C6: F01, p. 8
A7: Amortizações de dívida em 2027 | B7: 1672 | C7: F01, p. 8
A8: Cobertura de 2026 (caixa / amortizações 2026) | B8: =B5/B6 -> 1.8080271
A9: Fluxo de caixa operacional 2025 (R$ mi) | B9: 3028.446
A10: Alavancagem dívida líquida/EBITDA (faixa-alvo 2,5x a 3,1x) | B10: 2.7
A11: Liquidez corrente | B11: =Indicadores!B5 -> 0.98366861
A12: Leitura | B12: =IF(AND(B8>1,B10<=3.1),"Sem indício de incerteza relevante com dados públicos","Aprofundar") -> Sem indício de incerteza relevante com dados públicos

Sheet Expectativas_520
A1: Expectativas analíticas com limite de investigação - PT 520 (NBC TA 520, item 5)
A2: COPEL - exercício 2025 | Preparadora: matrícula 232025417 | Data: 24/10/2026 | Revisão: ____________ (campo não preenchido - sem revisão de terceiros)
A3: Limite de investigação = materialidade de execução | B3: =Materialidade!B14 -> 113633
A5: Item | B5: Esperado (R$ mil) | C5: Registrado (R$ mil) | D5: Diferença | E5: Investigar? | F5: Base da expectativa
A6: Custo nominal médio da dívida (F01, p. 7) | B6: 0.1322
A7: Despesa financeira | B7: =(Indicadores!B6+Indicadores!C6)/2*B6 -> 2462985.3 | C7: =-DRE!B29 -> 3142010 | D7: =C7-B7 -> 679024.72 | E7: =IF(ABS(D7)>$B$3,"Sim - investigar","Não") -> Sim - investigar | F7: Dívida média (empréstimos + debêntures) x custo nominal
A8: Depreciação e amortização | B8: =-DRE!C21/(BP!C43+BP!C44)*((BP!C43+BP!C44)+(BP!B43+BP!B44))/2 -> 1529944.7 | C8: =-DRE!B21 -> 1481886 | D8: =C8-B8 -> -48058.663 | E8: =IF(ABS(D8)>$B$3,"Sim - investigar","Não") -> Não | F8: Taxa implícita 2024 x base média 2025 (imobilizado + intangível)
A9: Receita de construção | B9: =-DRE!B23*(DRE!C10/-DRE!C23) -> 3308956.7 | C9: =DRE!B10 -> 3303150 | D9: =C9-B9 -> -5806.6941 | E9: =IF(ABS(D9)>$B$3,"Sim - investigar","Não") -> Não | F9: Custo 2025 x (1 + margem 2024)
A10: Dividendos mínimos a pagar | B10: 2450000 | C10: =BP!B57 -> 2325889 | D10: =C10-B10 -> -124111 | E10: =IF(ABS(D10)>$B$3,"Sim - investigar","Não") -> Sim - investigar | F10: Proventos declarados no 4T25: R$ 1,35 bi dividendos + R$ 1,1 bi JCP (F01, p. 1; F06)
A13: Investigação das diferenças com as notas explicativas (F17)
A14: Item | B14: Esperado (R$ mil) | C14: Registrado (R$ mil) | D14: Diferença | E14: Investigar? | F14: Fonte / leitura
A15: Encargos e variação monetária da dívida x expectativa | B15: =B7 -> 2462985.3 | C15: 2490902 | D15: =C15-B15 -> 27916.718 | E15: =IF(ABS(D15)>$B$3,"Sim - investigar","Não") -> Não | F15: F17, NE 30, p. 117: a parcela da dívida fica perto da expectativa
A16: Demais despesas financeiras (fora da dívida) | C16: =C7-C15 -> 651108 | F16: PIS/Cofins s/ JCP 129.067; concessões 157.858; CVA 77.774; PIS/Cofins 64.510; litígios 63.304; outros
A17: Dividendos a pagar: proventos - IRRF sobre JCP | B17: =2450000-168009 -> 2281991 | C17: =C10 -> 2325889 | D17: =C17-B17 -> 43898 | E17: =IF(ABS(D17)>$B$3,"Sim - investigar","Não") -> Não | F17: IRRF s/ JCP R$ 168.009 mil em outras obrigações fiscais (F17, NE 12.2, p. 81); resíduo não explicado

Sheet Sensibilidade_540
A1: Sensibilidade da PECLD à cobertura dos vencidos - PT 540 (R$ milhões)
A2: COPEL - exercício 2025 | Preparadora: matrícula 232025417 | Data: 24/10/2026 | Revisão: ____________ (campo não preenchido - sem revisão de terceiros)
A4: Vencidos líquidos de PECLD (F02, Item 3, p. 5) | B4: 605.5
A5: PECLD registrada (F02, Item 3, p. 5) | B5: 245.6
A6: Vencidos brutos (premissa: PECLD refere-se aos vencidos) | B6: =B4+B5 -> 851.1
A7: Cobertura atual | B7: =B5/B6 -> 0.28856774
A8: Materialidade de execução (R$ mi) | B8: =Materialidade!B14/1000 -> 113.633
A9: Materialidade global (R$ mi) | B9: =Materialidade!B12/1000 -> 162.333
A11: Cenário de cobertura | B11: PECLD no cenário | C11: Variação | D11: Comparação
A12: 0.2 | B12: =$B$6*A12 -> 170.22 | C12: =B12-$B$5 -> -75.38 | D12: =IF(ABS(C12)>$B$9,"Acima da global",IF(ABS(C12)>$B$8,"Acima da ME","Abaixo da ME")) -> Abaixo da ME
A13: 0.35 | B13: =$B$6*A13 -> 297.885 | C13: =B13-$B$5 -> 52.285 | D13: =IF(ABS(C13)>$B$9,"Acima da global",IF(ABS(C13)>$B$8,"Acima da ME","Abaixo da ME")) -> Abaixo da ME
A14: 0.4 | B14: =$B$6*A14 -> 340.44 | C14: =B14-$B$5 -> 94.84 | D14: =IF(ABS(C14)>$B$9,"Acima da global",IF(ABS(C14)>$B$8,"Acima da ME","Abaixo da ME")) -> Abaixo da ME
A15: 0.5 | B15: =$B$6*A15 -> 425.55 | C15: =B15-$B$5 -> 179.95 | D15: =IF(ABS(C15)>$B$9,"Acima da global",IF(ABS(C15)>$B$8,"Acima da ME","Abaixo da ME")) -> Acima da global
A17: Cobertura que gera variação igual à materialidade global | B17: =(B5+B9)/B6 -> 0.4793009

Sheet Grupo_600
A1: Componentes e materialidade dos componentes - PT 600 (R$ mil)
A2: COPEL - exercício 2025 | Preparadora: matrícula 232025417 | Data: 24/10/2026 | Revisão: ____________ (campo não preenchido - sem revisão de terceiros)
A4: Materialidade de execução do grupo | B4: =Materialidade!B14 -> 113633
A6: Componente | B6: Receita líquida antes de eliminações (F01, Anexo II) | C6: % da soma | D6: % da ME do grupo | E6: Materialidade do componente
A7: Copel DIS | B7: 19202210 | C7: =B7/$B$18 -> 0.66285839 | D7: 0.75 | E7: =ROUND($B$4*D7,0) -> 85225
A8: Copel GeT - geração | B8: 2253075 | C8: =B8/$B$18 -> 0.077775926 | D8: 0.65 | E8: =ROUND($B$4*D8,0) -> 73861
A9: Copel GeT - transmissão | B9: 1097358 | C9: =B9/$B$18 -> 0.037880689 | D9: 0.65 | E9: =ROUND($B$4*D9,0) -> 73861
A10: Copel Comercialização | B10: 4402327 | C10: =B10/$B$18 -> 0.15196789 | D10: 0.4 | E10: =ROUND($B$4*D10,0) -> 45453
A11: Parques eólicos | B11: 877553 | C11: =B11/$B$18 -> 0.030293043 | D11: 0.25 | E11: =ROUND($B$4*D11,0) -> 28408
A12: F.D.A. | B12: 598908 | C12: =B12/$B$18 -> 0.020674245 | D12: 0.25 | E12: =ROUND($B$4*D12,0) -> 28408
A13: Elejor | B13: 153989 | C13: =B13/$B$18 -> 0.005315685 | D13: 0.25 | E13: =ROUND($B$4*D13,0) -> 28408
A14: C. Oeste, Marumbi, Uirapuru | B14: 303765 | C14: =B14/$B$18 -> 0.010485938 | D14: 0.25 | E14: =ROUND($B$4*D14,0) -> 28408
A15: Bela Vista | B15: 39744 | C15: =B15/$B$18 -> 0.0013719589 | D15: 0.25 | E15: =ROUND($B$4*D15,0) -> 28408
A16: Pequenos ativos | B16: 27740 | C16: =B16/$B$18 -> 0.00095758205 | D16: 0.25 | E16: =ROUND($B$4*D16,0) -> 28408
A17: Copel Serviços | B17: 12128 | C17: =B17/$B$18 -> 0.00041865736 | D17: 0.25 | E17: =ROUND($B$4*D17,0) -> 28408
A18: Soma dos componentes | B18: =SUM(B7:B17) -> 28968797
A19: Eliminações (F01, Anexo II) | B19: -2851941
A20: Receita consolidada (soma + eliminações) | B20: =B18+B19 -> 26116856 | C20: =IF(B20=DRE!B6,"Confere com DRE","DIFERENÇA") -> Confere com DRE
A21: Cobertura DIS + GeT (auditoria completa) | B21: =SUM(C7:C9) -> 0.778515

Sheet Matriz_Cobertura
A1: Matriz de cobertura das normas - PT MC
A2: COPEL - exercício 2025 | Preparadora: matrícula 232025417 | Data: 24/10/2026 | Revisão: ____________ (campo não preenchido - sem revisão de terceiros)
A4: Norma | B4: Versão (2025) | C4: Publicação | D4: Título | E4: PT principais | F4: PT de apoio
A5: NBC TA Estrutura Conceitual | B5: Estrutura Conceitual | C5: DOU 25/11/2015 | D5: Estrutura Conceitual para Trabalhos de Asseguração | E5: PT EC
A6: NBC TA 200 | B6: NBC TA 200 (R1) | C6: DOU 05/09/2016 | D6: Objetivos Gerais do Auditor Independente e a Condução da Auditoria | E6: PT 200, PT RA, PT CI | F6: PT EC, PT 500.2
A7: NBC TA 210 | B7: NBC TA 210 (R1) | C7: DOU 05/09/2016 | D7: Concordância com os Termos do Trabalho de Auditoria | E7: PT 210
A8: NBC TA 220 | B8: NBC TA 220 (R3) | C8: DOU 09/12/2021 | D8: Gestão de Qualidade da Auditoria de Demonstrações Contábeis | E8: PT 220 | F8: PT 300, PT 600
A9: NBC TA 230 | B9: NBC TA 230 (R1) | C9: DOU 05/09/2016 | D9: Documentação de Auditoria | E9: PT 000, PT 230, PT BS-03, PT MC | F9: PT 500.2, PT 220, PT BS-02
A10: NBC TA 240 | B10: NBC TA 240 (R1) | C10: DOU 05/09/2016 | D10: Responsabilidade do Auditor em Relação a Fraude | E10: PT 240 | F10: PT 315.2, PT PA-01, PT BS-05
A11: NBC TA 250 | B11: NBC TA 250 | C11: DOU 14/02/2019 | D11: Consideração de Leis e Regulamentos | E11: PT 250 | F11: PT 315.1
A12: NBC TA 260 | B12: NBC TA 260 (R2) | C12: DOU 04/07/2016 | D12: Comunicação com os Responsáveis pela Governança | E12: PT 260 | F12: PT RA
A13: NBC TA 265 | B13: NBC TA 265 | C13: Res. CFC 1.210/2009 | D13: Comunicação de Deficiências de Controle Interno | E13: PT 265 | F13: PT 260
A14: NBC TA 300 | B14: NBC TA 300 (R1) | C14: DOU 05/09/2016 | D14: Planejamento da Auditoria de Demonstrações Contábeis | E14: PT 300 | F14: PT 000
A15: NBC TA 315 | B15: NBC TA 315 (R2) | C15: DOU 02/09/2021 | D15: Identificação e Avaliação dos Riscos de Distorção Relevante | E15: PT 315.1, PT 315.2 | F15: PT 240, PT 265, PT 330, PT BS-01
A16: NBC TA 320 | B16: NBC TA 320 (R1) | C16: DOU 05/09/2016 | D16: Materialidade no Planejamento e na Execução da Auditoria | E16: PT 320, PT BS-01 | F16: PT 450
A17: NBC TA 330 | B17: NBC TA 330 (R1) | C17: DOU 05/09/2016 | D17: Resposta do Auditor aos Riscos Avaliados | E17: PT 330, PT PA-01, PT PA-02, PT PA-03, PT PA-04, PT PA-05, PT BS-05 | F17: PT 240, PT PA-06, PT BS-04
A18: NBC TA 402 | B18: NBC TA 402 | C18: Res. CFC 1.215/2009 | D18: Considerações de Auditoria para a Entidade que Utiliza Organização Prestadora de Serviços | E18: PT 402
A19: NBC TA 450 | B19: NBC TA 450 (R1) | C19: DOU 05/09/2016 | D19: Avaliação das Distorções Identificadas | E19: PT 450, PT BS-06 | F19: PT 320, PT 530, PT CI
A20: NBC TA 500 | B20: NBC TA 500 (R1) | C20: DOU 05/09/2016 | D20: Evidência de Auditoria | E20: PT 500.2, PT 500.1, PT BS-02, PT BS-04
A21: NBC TA 501 | B21: NBC TA 501 | C21: Res. CFC 1.218/2009 | D21: Evidência de Auditoria - Considerações Específicas para Itens Selecionados | E21: PT 501 | F21: PT PA-03, PT PA-05
A22: NBC TA 505 | B22: NBC TA 505 | C22: Res. CFC 1.219/2009 | D22: Confirmações Externas | E22: PT 505 | F22: PT 501, PT PA-02, PT PA-05
A23: NBC TA 510 | B23: NBC TA 510 (R1) | C23: DOU 05/09/2016 | D23: Trabalhos Iniciais - Saldos Iniciais | E23: PT 510
A24: NBC TA 520 | B24: NBC TA 520 | C24: Res. CFC 1.221/2009 | D24: Procedimentos Analíticos | E24: PT 520 | F24: PT PA-01, PT BS-05
A25: NBC TA 530 | B25: NBC TA 530 | C25: Res. CFC 1.222/2009 | D25: Amostragem em Auditoria | E25: PT 530 | F25: PT 450, PT BS-06
A26: NBC TA 540 | B26: NBC TA 540 (R2) | C26: DOU 23/10/2019 | D26: Auditoria de Estimativas Contábeis, Inclusive do Valor Justo, e Divulgações Relacionadas | E26: PT 540, PT PA-06 | F26: PT 315.2, PT PA-04
A27: NBC TA 550 | B27: NBC TA 550 | C27: Res. CFC 1.224/2009 | D27: Partes Relacionadas | E27: PT 550
A28: NBC TA 560 | B28: NBC TA 560 (R1) | C28: DOU 05/09/2016 | D28: Eventos Subsequentes | E28: PT 560
A29: NBC TA 570 | B29: NBC TA 570 | C29: DOU 04/07/2016 | D29: Continuidade Operacional | E29: PT 570
A30: NBC TA 580 | B30: NBC TA 580 (R1) | C30: DOU 05/09/2016 | D30: Representações Formais | E30: PT 580
A31: NBC TA 600 | B31: NBC TA 600 (R2) | C31: DOU 06/12/2023 | D31: Considerações Especiais - Auditorias de Demonstrações Contábeis de Grupos | E31: PT 600
A33: Normas sem PT principal (contagem) | B33: =COUNTIF(E5:E31,"") -> 0

Sheet Fontes
A1: Relação de fontes (detalhe em docs/fontes.md)
A2: COPEL - exercício 2025 | Preparadora: matrícula 232025417 | Data: 24/10/2026 | Revisão: ____________ (campo não preenchido - sem revisão de terceiros)
A4: ID | B4: Documento | C4: Endereço eletrônico / páginas / exercício / acesso
A5: F01 | B5: Release de resultados 4T25 – Form 6-K (inclui Anexo I: DRE, balanço e DFC consolidados) | C5: https://www.sec.gov/Archives/edgar/data/1041792/000129281426000558/elppr4q25_6k.htm | Destaques (p. 1); seções 1.1 a 1.7 (pp. 4–8); seção 2 (p. 9); seção 3 (pp. 10–13); seção 4 (pp. 14–16); Anexo I: DRE p. 23, balanço p. 24, DFC p. 25, capital social p. 28 | 2025 e 2024 | 24/10/2026
A6: F02 | B6: Form 20-F 2025 (relatório anual arquivado na SEC em 15/04/2026; DFs consolidadas em IFRS; relatórios PwC F-3 e Deloitte F-7) | C6: https://www.sec.gov/Archives/edgar/data/1041792/000207097926000155/elpc-20251231.htm | Apresentação (p. 1); Item 3 – fatores de risco (pp. 3–19: vencidos e PECLD p. 5; provisões p. 7; clientes livres p. 12; Selic/IPCA p. 15; câmbio p. 18); Item 4 (pp. 20–26); Item 15 (p. 117); índice das DFs (F-3, F-7) | 2025 | 24/10/2026
A7: F03 | B7: Form 6-K de março/2026 – ata do Conselho de Administração de 26/02/2026 (aprovação das DFs 2025; parecer do Comitê de Auditoria Estatutário; relatório PwC sem ressalvas) | C7: https://www.sec.gov/Archives/edgar/data/1041792/000129281426000710/elp20260306_6k.htm | Itens 01 e manifestação do auditor externo | 2025 | 24/10/2026
A8: F04 | B8: Form 6-K de 11/03/2024 – contratação da PwC em substituição à Deloitte (até o exercício de 2028) | C8: https://www.sec.gov/Archives/edgar/data/1041792/000129281424000777/elp20240311_6k3.htm | Página única | 2024–2028 | 24/10/2026
A9: F05 | B9: Form 6-K de 22/12/2025 – conclusão da migração ao Novo Mercado | C9: https://www.sec.gov/Archives/edgar/data/1041792/000129281425004347/elp20251222_6k.htm | Página única | 2025 | 24/10/2026
A10: F06 | B10: Form 6-K de 10/12/2025 – dividendos de R$ 1,35 bilhão (data-base 30/12/2025) | C10: https://www.sec.gov/Archives/edgar/data/1041792/000129281425004224/elp20251210_6k.htm | Página única | 2025 | 24/10/2026
A11: F07 | B11: Relatório da Administração e DFs 2025 da F.D.A. Geração de Energia Elétrica S.A. (controlada indireta; relatório PwC de 20/03/2026) | C11: https://api.mziq.com/mzfilemanager/v2/d/16a31b1b-5ecd-4214-a2e0-308a2393e330/eabc7f9a-165e-5467-f639-e25c77de3a27?origin=2 | Balanço p. 8; NE 9 – intangível p. 20; NE 13 p. 22; NE 19 p. 26; NE 22 p. 27; relatório do auditor pp. 29–31 | 2025 | 24/10/2026
A12: F08 | B12: Form 6-K de 25/05/2026 – renegociação do UBP da Elejor | C12: https://www.sec.gov/Archives/edgar/data/0001041792/000129281426003179/elp20260525_6k.htm | Página única | 2026 (evento subsequente) | 24/10/2026
A13: F09 | B13: CFC – lista das NBC TA de auditoria independente (versões e publicações) | C13: https://cfc.org.br/tecnica/normas-brasileiras-de-contabilidade/nbc-ta-de-auditoria-independente/ | Tabela completa | Normas vigentes | 24/10/2026
A14: F10 | B14: DFs 2025 da Copel Geração e Transmissão S.A. publicadas no jornal Valor (honorários da PwC) | C14: https://s3.glbimg.com/v1/AUTH_63b422c2caee4269b8b34177e8876b93/valorri-uploads/bs/2026/Z/v/ZqsrDYSO65YBkjfbq47A/copelget1587812327022026.pdf | Nota sobre auditoria independente | 2025 | 24/10/2026
A15: F11 | B15: ITR de março/2026 da Copel Distribuição S.A. (referência às DFs de 31/12/2025; taxa média de amortização do intangível) | C15: https://api.mziq.com/mzfilemanager/v2/d/7f70f37b-33a7-497d-8a97-914a19f54edd/eb0b8e4a-0e97-7583-0908-659d0c24ac5f?origin=2 | Nota do intangível (trecho; leitura parcial) | 2025/2026 | 24/10/2026
... A23: F19 | B23: B3 – página da companhia COPEL (Empresas listadas): dados da companhia e outros códigos de negociação (CPLE3, ISIN BRCPLEACNOR8; CPLE99, ISIN BRCPLECDAXX8) | C23: https://www.b3.com.br (Produtos e Serviços > Empresas listadas > COPEL); consulta registrada por captura de tela da estudante | Seção “Dados da Companhia” | Situação em 24/10/2026 | 24/10/2026
